<?xml version='1.0' encoding='UTF-8'?>
<rss xmlns:atom="http://www.w3.org/2005/Atom" xmlns:content="http://purl.org/rss/1.0/modules/content/" version="2.0">
  <channel>
    <title>CVE Feed for python-social-auth -- all</title>
    <link>https://raw.githubusercontent.com/deepseas/cvelistV5monitor/main/feeds/python-social-auth/all.rss</link>
    <description>The latest CVEs for python-social-auth -- all products</description>
    <docs>http://www.rssboard.org/rss-specification</docs>
    <generator>python-feedgen</generator>
    <lastBuildDate>Tue, 04 Jun 2024 17:29:28 +0000</lastBuildDate>
    <ttl>60</ttl>
    <item>
      <title>CVE-2024-32879|2024-04-24T19:42:14.642Z -- python-social-auth -- social-app-django
</title>
      <link>https://cve.mitre.org/cgi-bin/cvename.cgi?name=CVE-2024-32879</link>
      <description>Python Social Auth is a social authentication/registration mechanism. Prior to version 5.4.1, due to default case-insensitive collation in MySQL or MariaDB databases, third-party authentication user IDs are not case-sensitive and could cause different IDs to match. This issue has been addressed by a fix released in version 5.4.1. An immediate workaround would be to change collation of the affected field.</description>
      <guid isPermaLink="false">CVE-2024-32879|2024-04-24T19:42:14.642Z</guid>
      <pubDate>Wed, 24 Apr 2024 19:42:14 +0000</pubDate>
    </item>
  </channel>
</rss>
